<?xml version="1.0" ?>

<robot name="RRPbot">

    <link name="base_link">
        <inertial>
            <origin xyz="0.0 0.0 0.0" rpy="0 0 0" />
            <mass value="0.01" />
            <inertia ixx="0.0000001" iyy="0.0000001" izz="0.0000001" ixy="0" ixz="0" iyz="0" />
        </inertial>
        <visual>
            <origin xyz="0.0 0.0 0.0" rpy="0 0 0" />
            <geometry>
                <box size="0.5 0.5 0.05" />
            </geometry>
        </visual>
    </link>

    <link name="link0">
        <inertial>
            <origin xyz="0.0 0.0 0.0" rpy="0 0 0" />
            <mass value="0.01" />
            <inertia ixx="0.0000001" iyy="0.0000001" izz="0.0000001" ixy="0" ixz="0" iyz="0" />
        </inertial>
        <visual>
            <origin xyz="0.0 0.0 0.025" rpy="0 0 0" />
            <geometry>
                <cylinder radius="0.1" length="0.05"/>
            </geometry>
        </visual>
        <visual>
            <origin xyz="0.0 0.0 0.125" rpy="0 0 0" />
            <geometry>
                <box size="0.1 0.1 0.15"/>
            </geometry>
        </visual>
    </link>

    <link name="link1">
        <inertial>
            <origin xyz="0.0 0.0 0.0" rpy="0 0 0" />
            <mass value="0.01" />
            <inertia ixx="0.0000001" iyy="0.0000001" izz="0.0000001" ixy="0" ixz="0" iyz="0" />
        </inertial>
        <visual>
            <origin xyz="0.0 0.0 -0.075" rpy="0 0 0" />
            <geometry>
                <cylinder radius="0.05" length="0.15"/>
            </geometry>
        </visual>
        <visual>
            <origin xyz="0.0 0.05 0.0" rpy="0 0 0" />
            <geometry>
                <box size="0.1 0.05 0.1" />
            </geometry>
        </visual>
    </link>

    <link name="link2">
        <inertial>
            <origin xyz="0.0 0.0 0.0" rpy="0 0 0" />
            <mass value="1" />
            <inertia ixx="0.0000001" iyy="0.0000001" izz="0.0000001" ixy="0" ixz="0" iyz="0" />
        </inertial>
        <visual>
            <origin xyz="0.0 0.0 -0.075" rpy="0 0 0" />
            <geometry>
                <box size="0.07 0.07 0.15" />
            </geometry>
        </visual>

        <visual>
            <origin xyz="0.0 0.0 0.0075" rpy="0 0 0" />
            <geometry>
                <sphere radius="0.015" />
            </geometry>
            <material name="material_red">
		        <color rgba="0.5 0.0 0.0 1.0" />
	        </material>
        </visual>

    </link>
    
    <joint name="j0" type="revolute">
        <parent link="base_link" />
        <child link="link0" />
        <origin xyz="0.000000 0.000000 0.000000" rpy="-0.000000 0.000000 -0.000000" />
        <axis xyz="0 0 1" />
        <limit lower="-2.967" upper="2.967" effort="176" velocity="1.7104" />
    </joint>

    <joint name="j1" type="revolute">
        <parent link="link0" />
        <child link="link1" />
        <origin xyz="0.000000 0.000000 0.20000" rpy="1.5708 0.000000 -0.000000" />
        <axis xyz="0 0 1" />
        <limit lower="-2.967" upper="2.967" effort="176" velocity="1.7104" />
    </joint>

    <joint name="j2" type="prismatic">
        <parent link="link1" />
        <child link="link2" />
        <origin xyz="0.000000 0.000000 0.000000" rpy="-1.5708 0.000000 -0.000000" />
        <axis xyz="0 0 1" />
        <limit lower="-2.967" upper="2.967" effort="176" velocity="1.7104" />
    </joint>
    
</robot>



