<?xml version="1.0" ?>

<robot name="sawyer">

  <link name="base">
    <visual>
        <origin rpy="1.57079632679 0 -1.57079632679" xyz="0.26 0.345 -0.91488"/>
        <geometry>
          <mesh filename="meshes/pedestal.obj"/>
        </geometry>
    </visual>
    <inertial>
        <origin rpy="0 0 0" xyz="0 0 0"/>
        <mass value="60.86397744"/>
        <inertia ixx="5.0635929" ixy="0.00103417" ixz="0.80199628" iyy="6.08689388" iyz="0.00105311" izz="4.96191932"/>
    </inertial>
  </link>

  <joint name="right_arm_mount" type="fixed">
    <origin rpy="0 0 0" xyz="0.0 0.0 0.0"/>
    <parent link="base"/>
    <child link="right_arm_base_link"/>
  </joint>

  <link name="right_arm_base_link">
    <inertial>
      <origin rpy="0 0 0" xyz="-0.0006241 -2.8025E-05 0.065404"/>
      <mass value="2.0687"/>
      <inertia ixx="0.0067599" ixy="-4.2024E-05" ixz="-6.1904E-07" iyy="0.0067877" iyz="1.5888E-05" izz="0.0074031"/>
    </inertial>
    <visual>
      <origin rpy="1.57 0 0" xyz="0 0 0"/>
      <geometry>
        <mesh filename="meshes/base.obj"/>
      </geometry>
    </visual>
  </link>

  <link name="right_l0">
    <inertial>
      <origin rpy="0 0 0" xyz="0.024366 0.010969 0.14363"/>
      <mass value="5.3213"/>
      <inertia ixx="0.053314" ixy="0.0047093" ixz="0.011734" iyy="0.057902" iyz="0.0080179" izz="0.023659"/>
    </inertial>
    <visual>
      <origin rpy="0 0 0" xyz="0 0 0"/>
      <geometry>
        <mesh filename="meshes/l0.obj"/>
      </geometry>
    </visual>
  </link>

  <joint name="right_j0" type="revolute">
    <origin rpy="0 0 0" xyz="0 0 0.08"/>
    <parent link="right_arm_base_link"/>
    <child link="right_l0"/>
    <axis xyz="0 0 1"/>
    <limit effort="80.0" lower="-3.0503" upper="3.0503" velocity="1.74"/>
  </joint>

  <link name="head">
    <inertial>
      <origin rpy="0 0 0" xyz="0.0053207 -2.6549E-05 0.1021"/>
      <mass value="1.5795"/>
      <inertia ixx="0.011833" ixy="-4.4669E-06" ixz="4.9425E-05" iyy="0.0082709" iyz="4.2124E-07" izz="0.0049661"/>
    </inertial>
    <visual>
      <origin rpy="1.57 0 0" xyz="0 0 0"/>
      <geometry>
        <mesh filename="meshes/head.obj"/>
      </geometry>
    </visual>
  </link>

  <joint name="head_pan" type="fixed"> <!-- Used to be revolute for head rotation -->
    <origin rpy="0 0 0" xyz="0 0 0.2965"/>
    <parent link="right_l0"/>
    <child link="head"/>
    <axis xyz="0 0 1"/>
    <limit effort="8" lower="-5.0952" upper="0.9064" velocity="1.8"/>
  </joint>

  <link name="right_l1">
    <inertial>
      <origin rpy="0 0 0" xyz="-0.0030849 -0.026811 0.092521"/>
      <mass value="4.505"/>
      <inertia ixx="0.022398" ixy="-0.00023986" ixz="-0.00029362" iyy="0.014613" iyz="-0.0060875" izz="0.017295"/>
    </inertial>
    <visual>
      <origin rpy="0 0 0" xyz="0 0 0"/>
      <geometry>
        <mesh filename="meshes/l1.obj"/>
      </geometry>
    </visual>
  </link>

  <joint name="right_j1" type="revolute">
    <origin rpy="-1.57079632679 1.57079632679 0" xyz="0.081 0.05 0.237"/>
    <parent link="right_l0"/>
    <child link="right_l1"/>
    <axis xyz="0 0 1"/>
    <limit effort="80.0" lower="-3.8095" upper="2.2736" velocity="1.328"/>
  </joint>

  <link name="right_l2">
    <inertial>
      <origin rpy="0 0 0" xyz="-0.00016044 -0.014967 0.13582"/>
      <mass value="1.745"/>
      <inertia ixx="0.025506" ixy="4.4101E-06" ixz="1.4955E-05" iyy="0.0253" iyz="-0.0033204" izz="0.0034179"/>
    </inertial>
    <visual>
      <origin rpy="1.57 0 0" xyz="0 0 0"/>
      <geometry>
        <mesh filename="meshes/l2.obj"/>
      </geometry>
    </visual>
  </link>

  <joint name="right_j2" type="revolute">
    <origin rpy="1.57079632679 0 0" xyz="0 -0.14 0.1325"/>
    <parent link="right_l1"/>
    <child link="right_l2"/>
    <axis xyz="0 0 1"/>
    <limit effort="40.0" lower="-3.0426" upper="3.0426" velocity="1.957"/>
  </joint>

  <link name="right_l3">
    <inertial>
      <origin rpy="0 0 0" xyz="-0.0048135 -0.0281 -0.084154"/>
      <mass value="2.5097"/>
      <inertia ixx="0.01016" ixy="-9.7452E-06" ixz="0.00026624" iyy="0.0065685" iyz="0.0030316" izz="0.0069078"/>
    </inertial>
    <visual>
      <origin rpy="1.57 0 0" xyz="0 0 0"/>
      <geometry>
        <mesh filename="meshes/l3.obj"/>
      </geometry>
    </visual>
  </link>

  <joint name="right_j3" type="revolute">
    <origin rpy="-1.57079632679 0 0" xyz="0 -0.042 0.26"/>
    <parent link="right_l2"/>
    <child link="right_l3"/>
    <axis xyz="0 0 1"/>
    <limit effort="40.0" lower="-3.0439" upper="3.0439" velocity="1.957"/>
  </joint>
  
  <link name="right_l4">
    <inertial>
      <origin rpy="0 0 0" xyz="-0.0018844 0.0069001 0.1341"/>
      <mass value="1.1136"/>
      <inertia ixx="0.013557" ixy="1.8109E-05" ixz="0.00013523" iyy="0.013555" iyz="0.0010561" izz="0.0013658"/>
    </inertial>
    <visual>
      <origin rpy="1.57 0 0" xyz="0 0 0"/>
      <geometry>
        <mesh filename="meshes/l4.obj"/>
      </geometry>
    </visual>
  </link>

  <joint name="right_j4" type="revolute">
    <origin rpy="1.57079632679 0 0" xyz="0 -0.125 -0.1265"/>
    <parent link="right_l3"/>
    <child link="right_l4"/>
    <axis xyz="0 0 1"/>
    <limit effort="9.0" lower="-2.9761" upper="2.9761" velocity="3.485"/>
  </joint>

  <link name="right_l5">
    <inertial>
      <origin rpy="0 0 0" xyz="0.0061133 -0.023697 0.076416"/>
      <mass value="1.5625"/>
      <inertia ixx="0.0047328" ixy="0.00011526" ixz="4.6269E-05" iyy="0.0029676" iyz="-0.0011557" izz="0.0031762"/>
    </inertial>
    <visual>
      <origin rpy="1.57 0 0" xyz="0 0 0"/>
      <geometry>
        <mesh filename="meshes/l5.obj"/>
      </geometry>
    </visual>
  </link>

  <joint name="right_j5" type="revolute">
    <origin rpy="-1.57079632679 0 0" xyz="0 0.031 0.275"/>
    <parent link="right_l4"/>
    <child link="right_l5"/>
    <axis xyz="0 0 1"/>
    <limit effort="9.0" lower="-2.9761" upper="2.9761" velocity="3.485"/>
  </joint>

  <!-- if camera position on arm needed -->
  <!-- 
  <link name="right_hand_camera"/>

  <joint name="right_hand_camera" type="fixed">
    <origin rpy="0 1.57079632679 0" xyz="0.039552 -0.033 0.0695"/>
    <parent link="right_l5"/>
    <child link="right_hand_camera"/>
    <axis xyz="0 0 0"/>
  </joint>
  -->

  <link name="right_l6">
    <inertial>
      <origin rpy="0 0 0" xyz="-8.0726E-06 0.0085838 -0.0049566"/>
      <mass value="0.3292"/>
      <inertia ixx="0.00031105" ixy="1.4771E-06" ixz="-3.7074E-07" iyy="0.00021549" iyz="-8.4533E-06" izz="0.00035976"/>
    </inertial>
    <visual>
      <origin rpy="0 0 0" xyz="0 0 0"/>
      <geometry>
        <mesh filename="meshes/l6.obj"/>
      </geometry>
    </visual>
  </link>

  <joint name="right_j6" type="revolute">
    <origin rpy="-1.57079632679 -0.17453 3.1416" xyz="0 -0.11 0.1053"/>
    <parent link="right_l5"/>
    <child link="right_l6"/>
    <axis xyz="0 0 1"/>
    <limit effort="9.0" lower="-4.7124" upper="4.7124" velocity="4.545"/>
  </joint>

  <!-- if camera position on head needed -->
  <!-- 
    <link name="head_camera"/>
  <joint name="head_camera" type="fixed">
    <origin rpy="-2.1293 0 -1.57079632679" xyz="0.0228027 0 0.216572"/>
    <parent link="head"/>
    <child link="head_camera"/>
    <axis xyz="0 0 0"/>
  </joint>
  -->

</robot>

